Workbook

Sheet Инструкция
A1: Проверка реестра подключаемых юридических лиц
A2: Учебный проект в Excel. Автор: Белорусцев Матвей Дмитриевич
A4: Задача
A5: Цель | B5: Смоделировать рабочую задачу аналитика по внедрению продукта: проверить данные о подключаемых организациях, найти ошибки, подготовить обратную связь для клиентов и итоговый реестр для передачи.
A6: Результат | B6: 400 организаций проверяются автоматически по 7 группам правил. Ошибки подсвечиваются, собираются в отдельный список с готовым текстом сообщения клиенту, а корректные записи попадают в финальный реестр.
A8: Листы файла
A9: Сводная | B9: Ключевые показатели, ошибки по типам (с диаграммой), результаты по регионам. Сводка построена формулами СЧЁТЕСЛИ / СЧЁТЕСЛИМН / СУММПРОИЗВ и содержит контрольные суммы.
A10: Реестр | B10: Исходные данные (синий шрифт, столбцы B–I) и проверки (коричневые заголовки). Красная заливка в ячейке данных означает найденную ошибку. Фильтры включены.
A11: Ошибки | B11: Автоматический список проблемных записей: описание ошибок и готовый текст сообщения клиенту.
A12: Финальный реестр | B12: Только записи со статусом «Готово к передаче».
A13: Справочники | B13: Коды регионов для функции ВПР.
A15: Что проверяется
A16: ИНН | B16: Не пустой; 10 цифр (юридическое лицо); только цифры; контрольная цифра по алгоритму ФНС (веса 2, 4, 10, 3, 5, 9, 4, 6, 8; остаток от деления на 11, затем на 10).
A17: ОГРН | B17: Не пустой; 13 цифр; только цифры; контрольная цифра = остаток от деления первых 12 цифр на 11 (если 10, то 0).
A18: КПП | B18: Не пустой; 9 знаков; формат; первые две цифры (регион) совпадают с ИНН.
A19: Дубликат ИНН | B19: ИНН не должен повторяться в реестре (СЧЁТЕСЛИ).
A20: Email | B20: Один символ @, точка после @, нет пробелов, не начинается с @ и не заканчивается точкой (упрощённая проверка).
A21: Телефон | B21: После удаления пробелов, дефисов, скобок и плюса остаётся 11 цифр, начинается с 7 или 8.
A22: Обязательные поля | B22: Заполнены наименование, адрес и контактное лицо.
A24: Как использовать со своими данными
A25: Шаги | B25: 1) Вставьте свои данные в столбцы B–I листа «Реестр», строки 2–401 (ИНН, ОГРН, КПП и телефон — как текст, чтобы не потерять ведущие нули). 2) Все проверки, сводка, список ошибок и финальный реестр пересчитаются сами. 3) Если записей больше 400, протяните формулы вниз и расширьте диапазоны.
A26: Реальная проверка | B26: Файл проверяет формат и контрольные цифры. Существование организации и актуальность реквизитов в работе нужно сверять по публичным государственным ресурсам (например, ЕГРЮЛ на сайте ФНС).
A28: Допущения
A29: Данные | B29: Все организации, ИНН, ОГРН, КПП, адреса, контакты, телефоны и email вымышлены и сгенерированы программой. Контрольные цифры подобраны по алгоритму, поэтому совпадения с реальными организациями случайны. Ошибки внесены намеренно (около трети записей). Email-адреса используют зарезервированный домен .example.
A30: Регион | B30: Регион определяется по первым двум цифрам ИНН через ВПР. В справочнике 15 регионов — это учебное допущение, не полный список.

Sheet Сводная
A1: Сводка по проверке реестра подключаемых организаций
A2: Все числа считаются формулами по листу «Реестр» и пересчитываются при изменении данных.
A3: Показатель | B3: Значение
A4: Всего организаций в реестре | B4: =COUNT(Реестр!A2:A401) -> 400
A5: Готово к передаче | B5: =COUNTIF(Реестр!S2:S401,"Готово к передаче") -> 282
A6: Требуют исправления | B6: =COUNTIF(Реестр!S2:S401,"Требует исправления") -> 118
A7: Доля готовых записей | B7: =IF(B4=0,0,B5/B4) -> 0.705
A8: Всего найдено ошибок | B8: =SUM(Реестр!R2:R401) -> 138
A9: В среднем ошибок на проблемную запись | B9: =IF(B6=0,0,B8/B6) -> 1.1694915
A11: Ошибки по типам
A12: Тип ошибки | B12: Записей с ошибкой | C12: Доля от всех записей
A13: ИНН (пустой, длина, символы, контрольная цифра) | B13: =SUMPRODUCT(--(LEN(Реестр!K2:K401)>0)) -> 32 | C13: =IF($B$4=0,0,B13/$B$4) -> 0.08
A14: ОГРН (пустой, длина, символы, контрольная цифра) | B14: =SUMPRODUCT(--(LEN(Реестр!L2:L401)>0)) -> 16 | C14: =IF($B$4=0,0,B14/$B$4) -> 0.04
A15: КПП (пустой, формат, регион не совпадает с ИНН) | B15: =SUMPRODUCT(--(LEN(Реестр!M2:M401)>0)) -> 24 | C15: =IF($B$4=0,0,B15/$B$4) -> 0.06
A16: Дубликат ИНН | B16: =SUMPRODUCT(--(LEN(Реестр!N2:N401)>0)) -> 24 | C16: =IF($B$4=0,0,B16/$B$4) -> 0.06
A17: Email | B17: =SUMPRODUCT(--(LEN(Реестр!O2:O401)>0)) -> 15 | C17: =IF($B$4=0,0,B17/$B$4) -> 0.0375
A18: Телефон | B18: =SUMPRODUCT(--(LEN(Реестр!P2:P401)>0)) -> 14 | C18: =IF($B$4=0,0,B18/$B$4) -> 0.035
A19: Обязательные поля (наименование, адрес, контакт) | B19: =SUMPRODUCT(--(LEN(Реестр!Q2:Q401)>0)) -> 13 | C19: =IF($B$4=0,0,B19/$B$4) -> 0.0325
A20: Итого ошибок (должно совпасть с «Всего найдено ошибок») | B20: =SUM(B13:B19) -> 138 | C20: =IF(B20=B8,"сходится","ОШИБКА") -> сходится
A22: Результаты по регионам (ВПР по первым цифрам ИНН)
A23: Регион | B23: Всего записей | C23: Требуют исправления | D23: Доля с ошибками
A24: =Справочники!B2 -> г. Москва | B24: =COUNTIF(Реестр!$J$2:$J$401,A24) -> 63 | C24: =COUNTIFS(Реестр!$J$2:$J$401,A24,Реестр!$S$2:$S$401,"Требует исправления") -> 15 | D24: =IF(B24=0,0,C24/B24) -> 0.23809524
A25: =Справочники!B3 -> г. Санкт-Петербург | B25: =COUNTIF(Реестр!$J$2:$J$401,A25) -> 48 | C25: =COUNTIFS(Реестр!$J$2:$J$401,A25,Реестр!$S$2:$S$401,"Требует исправления") -> 15 | D25: =IF(B25=0,0,C25/B25) -> 0.3125
A26: =Справочники!B4 -> г. Севастополь | B26: =COUNTIF(Реестр!$J$2:$J$401,A26) -> 36 | C26: =COUNTIFS(Реестр!$J$2:$J$401,A26,Реестр!$S$2:$S$401,"Требует исправления") -> 15 | D26: =IF(B26=0,0,C26/B26) -> 0.41666667
A27: =Справочники!B5 -> Республика Крым | B27: =COUNTIF(Реестр!$J$2:$J$401,A27) -> 26 | C27: =COUNTIFS(Реестр!$J$2:$J$401,A27,Реестр!$S$2:$S$401,"Требует исправления") -> 8 | D27: =IF(B27=0,0,C27/B27) -> 0.30769231
A28: =Справочники!B6 -> Московская область | B28: =COUNTIF(Реестр!$J$2:$J$401,A28) -> 21 | C28: =COUNTIFS(Реестр!$J$2:$J$401,A28,Реестр!$S$2:$S$401,"Требует исправления") -> 6 | D28: =IF(B28=0,0,C28/B28) -> 0.28571429
A29: =Справочники!B7 -> Краснодарский край | B29: =COUNTIF(Реестр!$J$2:$J$401,A29) -> 33 | C29: =COUNTIFS(Реестр!$J$2:$J$401,A29,Реестр!$S$2:$S$401,"Требует исправления") -> 7 | D29: =IF(B29=0,0,C29/B29) -> 0.21212121
A30: =Справочники!B8 -> Республика Татарстан | B30: =COUNTIF(Реестр!$J$2:$J$401,A30) -> 19 | C30: =COUNTIFS(Реестр!$J$2:$J$401,A30,Реестр!$S$2:$S$401,"Требует исправления") -> 7 | D30: =IF(B30=0,0,C30/B30) -> 0.36842105
A31: =Справочники!B9 -> Свердловская область | B31: =COUNTIF(Реестр!$J$2:$J$401,A31) -> 21 | C31: =COUNTIFS(Реестр!$J$2:$J$401,A31,Реестр!$S$2:$S$401,"Требует исправления") -> 5 | D31: =IF(B31=0,0,C31/B31) -> 0.23809524
A32: =Справочники!B10 -> Новосибирская область | B32: =COUNTIF(Реестр!$J$2:$J$401,A32) -> 23 | C32: =COUNTIFS(Реестр!$J$2:$J$401,A32,Реестр!$S$2:$S$401,"Требует исправления") -> 8 | D32: =IF(B32=0,0,C32/B32) -> 0.34782609
A33: =Справочники!B11 -> Нижегородская область | B33: =COUNTIF(Реестр!$J$2:$J$401,A33) -> 17 | C33: =COUNTIFS(Реестр!$J$2:$J$401,A33,Реестр!$S$2:$S$401,"Требует исправления") -> 4 | D33: =IF(B33=0,0,C33/B33) -> 0.23529412
A34: =Справочники!B12 -> Ростовская область | B34: =COUNTIF(Реестр!$J$2:$J$401,A34) -> 30 | C34: =COUNTIFS(Реестр!$J$2:$J$401,A34,Реестр!$S$2:$S$401,"Требует исправления") -> 10 | D34: =IF(B34=0,0,C34/B34) -> 0.33333333
A35: =Справочники!B13 -> Республика Башкортостан | B35: =COUNTIF(Реестр!$J$2:$J$401,A35) -> 11 | C35: =COUNTIFS(Реестр!$J$2:$J$401,A35,Реестр!$S$2:$S$401,"Требует исправления") -> 3 | D35: =IF(B35=0,0,C35/B35) -> 0.27272727
... A38: =Справочники!B16 -> Красноярский край | B38: =COUNTIF(Реестр!$J$2:$J$401,A38) -> 18 | C38: =COUNTIFS(Реестр!$J$2:$J$401,A38,Реестр!$S$2:$S$401,"Требует исправления") -> 3 | D38: =IF(B38=0,0,C38/B38) -> 0.16666667
A39: Регион не определён (ИНН пустой или с ошибкой) | B39: =COUNTIF(Реестр!$J$2:$J$401,"не определён") -> 6 | C39: =COUNTIFS(Реестр!$J$2:$J$401,"не определён",Реестр!$S$2:$S$401,"Требует исправления") -> 6 | D39: =IF(B39=0,0,C39/B39) -> 1
A40: Итого | B40: =SUM(B24:B39) -> 400 | C40: =SUM(C24:C39) -> 118 | D40: =IF(B40=0,0,C40/B40) -> 0.295 | E40: =IF(AND(B40=B4,C40=B6),"сходится","ОШИБКА") -> сходится

Sheet Реестр
A1: № | B1: Наименование организации | C1: ИНН | D1: ОГРН | E1: КПП | F1: Адрес | G1: Контактное лицо | H1: Email | I1: Телефон | J1: Регион (ВПР по ИНН) | K1: Проверка: ИНН | L1: Проверка: ОГРН | M1: Проверка: КПП | N1: Проверка: дубликат ИНН | O1: Проверка: email | P1: Проверка: телефон | Q1: Проверка: обязательные поля | R1: Число ошибок | S1: Статус | T1: Описание ошибок | U1: Сообщение клиенту | V1: № в списке ошибок (служебный) | W1: № в финальном реестре (служебный)
A2: 1 | B2: ООО «Эталон Принт» | C2: 2327503454 | D2: 5092327868474 | E2: 232701003 | F2: г. Краснодар, ул. Советская, д. 70, оф. 15 | G2: Иванова Е. С. | H2: sales@etalon-print.example | I2: +7 (861) 587-81-60 | J2: =IFERROR(VLOOKUP(VALUE(LEFT(C2,2)),Справочники!$A$2:$B$16,2,FALSE()),"не определён") -> Краснодарский край | K2: =IF(TRIM(C2)="","ИНН не указан",IF(LEN(C2)<>10,"ИНН: должно быть 10 цифр",IF(NOT(ISNUMBER(IFERROR(VALUE(C2),"x"))),"ИНН: есть нецифровые символы",IF(MOD(MOD(SUMPRODUCT(--MID(C2,{1,2,3,4,5,6,7,8,9},1),{2,4,10,3,5,9,4,6,8}),11),10)=VALUE(RIGHT(C2,1)),"","ИНН: неверная контрольная цифра")))) | L2: =IF(TRIM(D2)="","ОГРН не указан",IF(LEN(D2)<>13,"ОГРН: должно быть 13 цифр",IF(NOT(ISNUMBER(IFERROR(VALUE(D2),"x"))),"ОГРН: есть нецифровые символы",IF(MOD(VALUE(LEFT(D2,12))-11*INT(VALUE(LEFT(D2,12))/11),10)=VALUE(RIGHT(D2,1)),"","ОГРН: неверная контрольная цифра")))) | M2: =IF(TRIM(E2)="","КПП не указан",IF(LEN(E2)<>9,"КПП: должно быть 9 знаков",IF(NOT(AND(ISNUMBER(IFERROR(VALUE(LEFT(E2,4)),"x")),ISNUMBER(IFERROR(VALUE(RIGHT(E2,3)),"x")))),"КПП: неверный формат",IF(LEFT(E2,2)<>LEFT(C2,2),"КПП: код региона не совпадает с ИНН","")))) | N2: =IF(TRIM(C2)="","",IF(COUNTIF($C$2:$C$401,C2)>1,"Дубликат ИНН в реестре","")) | O2: =IF(TRIM(H2)="","Email не указан",IF(AND(ISNUMBER(FIND("@",H2)),ISNUMBER(FIND(".",H2,IFERROR(FIND("@",H2),1))),ISERROR(FIND(" ",H2)),LEFT(H2,1)<>"@",RIGHT(H2,1)<>".",LEN(H2)-LEN(SUBSTITUTE(H2,"@",""))=1),"","Email: неверный формат")) | P2: =IF(TRIM(I2)="","Телефон не указан",IF(AND(LEN(SUBSTITUTE(SUBSTITUTE(SUBSTITUTE(SUBSTITUTE(SUBSTITUTE(I2," ",""),"-",""),"(",""),")",""),"+",""))=11,OR(LEFT(SUBSTITUTE(SUBSTITUTE(SUBSTITUTE(SUBSTITUTE(SUBSTITUTE(I2," ",""),"-",""),"(",""),")",""),"+",""),1)="7",LEFT(SUBSTITUTE(SUBSTITUTE(SUBSTITUTE(SUBSTITUTE(SUBSTITUTE(I2," ",""),"-",""),"(",""),")",""),"+",""),1)="8"),ISNUMBER(IFERROR(VALUE(SUBSTITUTE(SUBSTITUTE(SUBSTITUTE(SUBSTITUTE(SUBSTITUTE(I2," ",""),"-",""),"(",""),")",""),"+","")),"x"))),"","Телефон: неверный формат")) | Q2: =TRIM(IF(TRIM(B2)="","Нет наименования. ","")&IF(TRIM(F2)="","Нет адреса. ","")&IF(TRIM(G2)="","Нет контактного лица.","")) | R2: =SUMPRODUCT(--(LEN(K2:Q2)>0)) -> 0 | S2: =IF(R2=0,"Готово к передаче","Требует исправления") -> Готово к передаче | T2: =IF(R2=0,"",_xlfn.TEXTJOIN("; ",TRUE(),K2:Q2)) | U2: =IF(R2=0,"","Здравствуйте! В данных организации «"&B2&"» обнаружены ошибки: "&T2&". Просим проверить и прислать исправленную информацию.") | V2: =IF(R2>0,COUNTIF($R$2:R2,">0"),"") | W2: =IF(R2=0,COUNTIF($R$2:R2,0),"") -> 1
A3: 2 | B3: ООО «Меридиан Стандарт» | C3: 7821181744 | D3: 1077836049818 | E3: 782145005 | F3: г. Санкт-Петербург, ул. Центральная, д. 82, оф. 267 | G3: Новиков О. М. | H3: mail@meridian-standart.example | I3: 8 812 5658356 | J3: =IFERROR(VLOOKUP(VALUE(LEFT(C3,2)),Справочники!$A$2:$B$16,2,FALSE()),"не определён") -> г. Санкт-Петербург | K3: =IF(TRIM(C3)="","ИНН не указан",IF(LEN(C3)<>10,"ИНН: должно быть 10 цифр",IF(NOT(ISNUMBER(IFERROR(VALUE(C3),"x"))),"ИНН: есть нецифровые символы",IF(MOD(MOD(SUMPRODUCT(--MID(C3,{1,2,3,4,5,6,7,8,9},1),{2,4,10,3,5,9,4,6,8}),11),10)=VALUE(RIGHT(C3,1)),"","ИНН: неверная контрольная цифра")))) | L3: =IF(TRIM(D3)="","ОГРН не указан",IF(LEN(D3)<>13,"ОГРН: должно быть 13 цифр",IF(NOT(ISNUMBER(IFERROR(VALUE(D3),"x"))),"ОГРН: есть нецифровые символы",IF(MOD(VALUE(LEFT(D3,12))-11*INT(VALUE(LEFT(D3,12))/11),10)=VALUE(RIGHT(D3,1)),"","ОГРН: неверная контрольная цифра")))) | M3: =IF(TRIM(E3)="","КПП не указан",IF(LEN(E3)<>9,"КПП: должно быть 9 знаков",IF(NOT(AND(ISNUMBER(IFERROR(VALUE(LEFT(E3,4)),"x")),ISNUMBER(IFERROR(VALUE(RIGHT(E3,3)),"x")))),"КПП: неверный формат",IF(LEFT(E3,2)<>LEFT(C3,2),"КПП: код региона не совпадает с ИНН","")))) | N3: =IF(TRIM(C3)="","",IF(COUNTIF($C$2:$C$401,C3)>1,"Дубликат ИНН в реестре","")) | O3: =IF(TRIM(H3)="","Email не указан",IF(AND(ISNUMBER(FIND("@",H3)),ISNUMBER(FIND(".",H3,IFERROR(FIND("@",H3),1))),ISERROR(FIND(" ",H3)),LEFT(H3,1)<>"@",RIGHT(H3,1)<>".",LEN(H3)-LEN(SUBSTITUTE(H3,"@",""))=1),"","Email: неверный формат")) | P3: =IF(TRIM(I3)="","Телефон не указан",IF(AND(LEN(SUBSTITUTE(SUBSTITUTE(SUBSTITUTE(SUBSTITUTE(SUBSTITUTE(I3," ",""),"-",""),"(",""),")",""),"+",""))=11,OR(LEFT(SUBSTITUTE(SUBSTITUTE(SUBSTITUTE(SUBSTITUTE(SUBSTITUTE(I3," ",""),"-",""),"(",""),")",""),"+",""),1)="7",LEFT(SUBSTITUTE(SUBSTITUTE(SUBSTITUTE(SUBSTITUTE(SUBSTITUTE(I3," ",""),"-",""),"(",""),")",""),"+",""),1)="8"),ISNUMBER(IFERROR(VALUE(SUBSTITUTE(SUBSTITUTE(SUBSTITUTE(SUBSTITUTE(SUBSTITUTE(I3," ",""),"-",""),"(",""),")",""),"+","")),"x"))),"","Телефон: неверный формат")) | Q3: =TRIM(IF(TRIM(B3)="","Нет наименования. ","")&IF(TRIM(F3)="","Нет адреса. ","")&IF(TRIM(G3)="","Нет контактного лица.","")) | R3: =SUMPRODUCT(--(LEN(K3:Q3)>0)) -> 0 | S3: =IF(R3=0,"Готово к передаче","Требует исправления") -> Готово к передаче | T3: =IF(R3=0,"",_xlfn.TEXTJOIN("; ",TRUE(),K3:Q3)) | U3: =IF(R3=0,"","Здравствуйте! В данных организации «"&B3&"» обнаружены ошибки: "&T3&". Просим проверить и прислать исправленную информацию.") | V3: =IF(R3>0,COUNTIF($R$2:R3,">0"),"") | W3: =IF(R3=0,COUNTIF($R$2:R3,0),"") -> 2
A4: 3 | B4: ООО «Горизонт Консалт» | C4: 7715736088 | D4: 5127713491164 | E4: 771501008 | F4: г. Москва, ул. Кирова, д. 59, оф. 281 | G4: Павлов О. С. | H4: zakaz@gorizont-konsalt.example | I4: +74955165983 | J4: =IFERROR(VLOOKUP(VALUE(LEFT(C4,2)),Справочники!$A$2:$B$16,2,FALSE()),"не определён") -> г. Москва | K4: =IF(TRIM(C4)="","ИНН не указан",IF(LEN(C4)<>10,"ИНН: должно быть 10 цифр",IF(NOT(ISNUMBER(IFERROR(VALUE(C4),"x"))),"ИНН: есть нецифровые символы",IF(MOD(MOD(SUMPRODUCT(--MID(C4,{1,2,3,4,5,6,7,8,9},1),{2,4,10,3,5,9,4,6,8}),11),10)=VALUE(RIGHT(C4,1)),"","ИНН: неверная контрольная цифра")))) | L4: =IF(TRIM(D4)="","ОГРН не указан",IF(LEN(D4)<>13,"ОГРН: должно быть 13 цифр",IF(NOT(ISNUMBER(IFERROR(VALUE(D4),"x"))),"ОГРН: есть нецифровые символы",IF(MOD(VALUE(LEFT(D4,12))-11*INT(VALUE(LEFT(D4,12))/11),10)=VALUE(RIGHT(D4,1)),"","ОГРН: неверная контрольная цифра")))) | M4: =IF(TRIM(E4)="","КПП не указан",IF(LEN(E4)<>9,"КПП: должно быть 9 знаков",IF(NOT(AND(ISNUMBER(IFERROR(VALUE(LEFT(E4,4)),"x")),ISNUMBER(IFERROR(VALUE(RIGHT(E4,3)),"x")))),"КПП: неверный формат",IF(LEFT(E4,2)<>LEFT(C4,2),"КПП: код региона не совпадает с ИНН","")))) | N4: =IF(TRIM(C4)="","",IF(COUNTIF($C$2:$C$401,C4)>1,"Дубликат ИНН в реестре","")) | O4: =IF(TRIM(H4)="","Email не указан",IF(AND(ISNUMBER(FIND("@",H4)),ISNUMBER(FIND(".",H4,IFERROR(FIND("@",H4),1))),ISERROR(FIND(" ",H4)),LEFT(H4,1)<>"@",RIGHT(H4,1)<>".",LEN(H4)-LEN(SUBSTITUTE(H4,"@",""))=1),"","Email: неверный формат")) | P4: =IF(TRIM(I4)="","Телефон не указан",IF(AND(LEN(SUBSTITUTE(SUBSTITUTE(SUBSTITUTE(SUBSTITUTE(SUBSTITUTE(I4," ",""),"-",""),"(",""),")",""),"+",""))=11,OR(LEFT(SUBSTITUTE(SUBSTITUTE(SUBSTITUTE(SUBSTITUTE(SUBSTITUTE(I4," ",""),"-",""),"(",""),")",""),"+",""),1)="7",LEFT(SUBSTITUTE(SUBSTITUTE(SUBSTITUTE(SUBSTITUTE(SUBSTITUTE(I4," ",""),"-",""),"(",""),")",""),"+",""),1)="8"),ISNUMBER(IFERROR(VALUE(SUBSTITUTE(SUBSTITUTE(SUBSTITUTE(SUBSTITUTE(SUBSTITUTE(I4," ",""),"-",""),"(",""),")",""),"+","")),"x"))),"","Телефон: неверный формат")) | Q4: =TRIM(IF(TRIM(B4)="","Нет наименования. ","")&IF(TRIM(F4)="","Нет адреса. ","")&IF(TRIM(G4)="","Нет контактного лица.","")) | R4: =SUMPRODUCT(--(LEN(K4:Q4)>0)) -> 0 | S4: =IF(R4=0,"Готово к передаче","Требует исправления") -> Готово к передаче | T4: =IF(R4=0,"",_xlfn.TEXTJOIN("; ",TRUE(),K4:Q4)) | U4: =IF(R4=0,"","Здравствуйте! В данных организации «"&B4&"» обнаружены ошибки: "&T4&". Просим проверить и прислать исправленную информацию.") | V4: =IF(R4>0,COUNTIF($R$2:R4,">0"),"") | W4: =IF(R4=0,COUNTIF($R$2:R4,0),"") -> 3
A5: 4 | B5: АО «Меридиан Монтаж» | D5: 1049120488625 | E5: 910345005 | F5: г. Симферополь, ул. Советская, д. 92, оф. 52 | G5: Иванов В. О. | H5: info@meridian-montazh.example | I5: +73655321609 | J5: =IFERROR(VLOOKUP(VALUE(LEFT(C5,2)),Справочники!$A$2:$B$16,2,FALSE()),"не определён") -> не определён | K5: =IF(TRIM(C5)="","ИНН не указан",IF(LEN(C5)<>10,"ИНН: должно быть 10 цифр",IF(NOT(ISNUMBER(IFERROR(VALUE(C5),"x"))),"ИНН: есть нецифровые символы",IF(MOD(MOD(SUMPRODUCT(--MID(C5,{1,2,3,4,5,6,7,8,9},1),{2,4,10,3,5,9,4,6,8}),11),10)=VALUE(RIGHT(C5,1)),"","ИНН: неверная контрольная цифра")))) -> ИНН не указан | L5: =IF(TRIM(D5)="","ОГРН не указан",IF(LEN(D5)<>13,"ОГРН: должно быть 13 цифр",IF(NOT(ISNUMBER(IFERROR(VALUE(D5),"x"))),"ОГРН: есть нецифровые символы",IF(MOD(VALUE(LEFT(D5,12))-11*INT(VALUE(LEFT(D5,12))/11),10)=VALUE(RIGHT(D5,1)),"","ОГРН: неверная контрольная цифра")))) | M5: =IF(TRIM(E5)="","КПП не указан",IF(LEN(E5)<>9,"КПП: должно быть 9 знаков",IF(NOT(AND(ISNUMBER(IFERROR(VALUE(LEFT(E5,4)),"x")),ISNUMBER(IFERROR(VALUE(RIGHT(E5,3)),"x")))),"КПП: неверный формат",IF(LEFT(E5,2)<>LEFT(C5,2),"КПП: код региона не совпадает с ИНН","")))) -> КПП: код региона не совпадает с ИНН | N5: =IF(TRIM(C5)="","",IF(COUNTIF($C$2:$C$401,C5)>1,"Дубликат ИНН в реестре","")) | O5: =IF(TRIM(H5)="","Email не указан",IF(AND(ISNUMBER(FIND("@",H5)),ISNUMBER(FIND(".",H5,IFERROR(FIND("@",H5),1))),ISERROR(FIND(" ",H5)),LEFT(H5,1)<>"@",RIGHT(H5,1)<>".",LEN(H5)-LEN(SUBSTITUTE(H5,"@",""))=1),"","Email: неверный формат")) | P5: =IF(TRIM(I5)="","Телефон не указан",IF(AND(LEN(SUBSTITUTE(SUBSTITUTE(SUBSTITUTE(SUBSTITUTE(SUBSTITUTE(I5," ",""),"-",""),"(",""),")",""),"+",""))=11,OR(LEFT(SUBSTITUTE(SUBSTITUTE(SUBSTITUTE(SUBSTITUTE(SUBSTITUTE(I5," ",""),"-",""),"(",""),")",""),"+",""),1)="7",LEFT(SUBSTITUTE(SUBSTITUTE(SUBSTITUTE(SUBSTITUTE(SUBSTITUTE(I5," ",""),"-",""),"(",""),")",""),"+",""),1)="8"),ISNUMBER(IFERROR(VALUE(SUBSTITUTE(SUBSTITUTE(SUBSTITUTE(SUBSTITUTE(SUBSTITUTE(I5," ",""),"-",""),"(",""),")",""),"+","")),"x"))),"","Телефон: неверный формат")) | Q5: =TRIM(IF(TRIM(B5)="","Нет наименования. ","")&IF(TRIM(F5)="","Нет адреса. ","")&IF(TRIM(G5)="","Нет контактного лица.","")) | R5: =SUMPRODUCT(--(LEN(K5:Q5)>0)) -> 2 | S5: =IF(R5=0,"Готово к передаче","Требует исправления") -> Требует исправления | T5: =IF(R5=0,"",_xlfn.TEXTJOIN("; ",TRUE(),K5:Q5)) -> ИНН не указан; КПП: код региона не совпадает с ИНН | U5: =IF(R5=0,"","Здравствуйте! В данных организации «"&B5&"» обнаружены ошибки: "&T5&". Просим проверить и прислать исправленную информацию.") -> Здравствуйте! В данных организации «АО «Меридиан Монтаж»» обнаружены ошибки: ИНН не указан; КПП: код региона не совпадает с ИНН. Просим проверить и прислать исправленную информацию. | V5: =IF(R5>0,COUNTIF($R$2:R5,">0"),"") -> 1 | W5: =IF(R5=0,COUNTIF($R$2:R5,0),"")
A6: 5 | B6: АО «Линия Сервис» | C6: 7733137520 | D6: 1067747510148 | E6: 773301009 | F6: г. Москва, ул. Школьная, д. 40, оф. 22 | G6: Алексеев В. Е. | H6: sales@liniya-servis.example | I6: 8 495 5942577 | J6: =IFERROR(VLOOKUP(VALUE(LEFT(C6,2)),Справочники!$A$2:$B$16,2,FALSE()),"не определён") -> г. Москва | K6: =IF(TRIM(C6)="","ИНН не указан",IF(LEN(C6)<>10,"ИНН: должно быть 10 цифр",IF(NOT(ISNUMBER(IFERROR(VALUE(C6),"x"))),"ИНН: есть нецифровые символы",IF(MOD(MOD(SUMPRODUCT(--MID(C6,{1,2,3,4,5,6,7,8,9},1),{2,4,10,3,5,9,4,6,8}),11),10)=VALUE(RIGHT(C6,1)),"","ИНН: неверная контрольная цифра")))) | L6: =IF(TRIM(D6)="","ОГРН не указан",IF(LEN(D6)<>13,"ОГРН: должно быть 13 цифр",IF(NOT(ISNUMBER(IFERROR(VALUE(D6),"x"))),"ОГРН: есть нецифровые символы",IF(MOD(VALUE(LEFT(D6,12))-11*INT(VALUE(LEFT(D6,12))/11),10)=VALUE(RIGHT(D6,1)),"","ОГРН: неверная контрольная цифра")))) | M6: =IF(TRIM(E6)="","КПП не указан",IF(LEN(E6)<>9,"КПП: должно быть 9 знаков",IF(NOT(AND(ISNUMBER(IFERROR(VALUE(LEFT(E6,4)),"x")),ISNUMBER(IFERROR(VALUE(RIGHT(E6,3)),"x")))),"КПП: неверный формат",IF(LEFT(E6,2)<>LEFT(C6,2),"КПП: код региона не совпадает с ИНН","")))) | N6: =IF(TRIM(C6)="","",IF(COUNTIF($C$2:$C$401,C6)>1,"Дубликат ИНН в реестре","")) | O6: =IF(TRIM(H6)="","Email не указан",IF(AND(ISNUMBER(FIND("@",H6)),ISNUMBER(FIND(".",H6,IFERROR(FIND("@",H6),1))),ISERROR(FIND(" ",H6)),LEFT(H6,1)<>"@",RIGHT(H6,1)<>".",LEN(H6)-LEN(SUBSTITUTE(H6,"@",""))=1),"","Email: неверный формат")) | P6: =IF(TRIM(I6)="","Телефон не указан",IF(AND(LEN(SUBSTITUTE(SUBSTITUTE(SUBSTITUTE(SUBSTITUTE(SUBSTITUTE(I6," ",""),"-",""),"(",""),")",""),"+",""))=11,OR(LEFT(SUBSTITUTE(SUBSTITUTE(SUBSTITUTE(SUBSTITUTE(SUBSTITUTE(I6," ",""),"-",""),"(",""),")",""),"+",""),1)="7",LEFT(SUBSTITUTE(SUBSTITUTE(SUBSTITUTE(SUBSTITUTE(SUBSTITUTE(I6," ",""),"-",""),"(",""),")",""),"+",""),1)="8"),ISNUMBER(IFERROR(VALUE(SUBSTITUTE(SUBSTITUTE(SUBSTITUTE(SUBSTITUTE(SUBSTITUTE(I6," ",""),"-",""),"(",""),")",""),"+","")),"x"))),"","Телефон: неверный формат")) | Q6: =TRIM(IF(TRIM(B6)="","Нет наименования. ","")&IF(TRIM(F6)="","Нет адреса. ","")&IF(TRIM(G6)="","Нет контактного лица.","")) | R6: =SUMPRODUCT(--(LEN(K6:Q6)>0)) -> 0 | S6: =IF(R6=0,"Готово к передаче","Требует исправления") -> Готово к передаче | T6: =IF(R6=0,"",_xlfn.TEXTJOIN("; ",TRUE(),K6:Q6)) | U6: =IF(R6=0,"","Здравствуйте! В данных организации «"&B6&"» обнаружены ошибки: "&T6&". Просим проверить и прислать исправленную информацию.") | V6: =IF(R6>0,COUNTIF($R$2:R6,">0"),"") | W6: =IF(R6=0,COUNTIF($R$2:R6,0),"") -> 4
A7: 6 | B7: ООО «Феникс Фуд» | C7: 2339849062 | D7: 5152323704341 | E7: 233901009 | F7: г. Краснодар, ул. Ленина, д. 23, оф. 162 | G7: Попов И. А. | H7: sales@feniks-fud.example | I7: +78615122366 | J7: =IFERROR(VLOOKUP(VALUE(LEFT(C7,2)),Справочники!$A$2:$B$16,2,FALSE()),"не определён") -> Краснодарский край | K7: =IF(TRIM(C7)="","ИНН не указан",IF(LEN(C7)<>10,"ИНН: должно быть 10 цифр",IF(NOT(ISNUMBER(IFERROR(VALUE(C7),"x"))),"ИНН: есть нецифровые символы",IF(MOD(MOD(SUMPRODUCT(--MID(C7,{1,2,3,4,5,6,7,8,9},1),{2,4,10,3,5,9,4,6,8}),11),10)=VALUE(RIGHT(C7,1)),"","ИНН: неверная контрольная цифра")))) | L7: =IF(TRIM(D7)="","ОГРН не указан",IF(LEN(D7)<>13,"ОГРН: должно быть 13 цифр",IF(NOT(ISNUMBER(IFERROR(VALUE(D7),"x"))),"ОГРН: есть нецифровые символы",IF(MOD(VALUE(LEFT(D7,12))-11*INT(VALUE(LEFT(D7,12))/11),10)=VALUE(RIGHT(D7,1)),"","ОГРН: неверная контрольная цифра")))) | M7: =IF(TRIM(E7)="","КПП не указан",IF(LEN(E7)<>9,"КПП: должно быть 9 знаков",IF(NOT(AND(ISNUMBER(IFERROR(VALUE(LEFT(E7,4)),"x")),ISNUMBER(IFERROR(VALUE(RIGHT(E7,3)),"x")))),"КПП: неверный формат",IF(LEFT(E7,2)<>LEFT(C7,2),"КПП: код региона не совпадает с ИНН","")))) | N7: =IF(TRIM(C7)="","",IF(COUNTIF($C$2:$C$401,C7)>1,"Дубликат ИНН в реестре","")) | O7: =IF(TRIM(H7)="","Email не указан",IF(AND(ISNUMBER(FIND("@",H7)),ISNUMBER(FIND(".",H7,IFERROR(FIND("@",H7),1))),ISERROR(FIND(" ",H7)),LEFT(H7,1)<>"@",RIGHT(H7,1)<>".",LEN(H7)-LEN(SUBSTITUTE(H7,"@",""))=1),"","Email: неверный формат")) | P7: =IF(TRIM(I7)="","Телефон не указан",IF(AND(LEN(SUBSTITUTE(SUBSTITUTE(SUBSTITUTE(SUBSTITUTE(SUBSTITUTE(I7," ",""),"-",""),"(",""),")",""),"+",""))=11,OR(LEFT(SUBSTITUTE(SUBSTITUTE(SUBSTITUTE(SUBSTITUTE(SUBSTITUTE(I7," ",""),"-",""),"(",""),")",""),"+",""),1)="7",LEFT(SUBSTITUTE(SUBSTITUTE(SUBSTITUTE(SUBSTITUTE(SUBSTITUTE(I7," ",""),"-",""),"(",""),")",""),"+",""),1)="8"),ISNUMBER(IFERROR(VALUE(SUBSTITUTE(SUBSTITUTE(SUBSTITUTE(SUBSTITUTE(SUBSTITUTE(I7," ",""),"-",""),"(",""),")",""),"+","")),"x"))),"","Телефон: неверный формат")) | Q7: =TRIM(IF(TRIM(B7)="","Нет наименования. ","")&IF(TRIM(F7)="","Нет адреса. ","")&IF(TRIM(G7)="","Нет контактного лица.","")) | R7: =SUMPRODUCT(--(LEN(K7:Q7)>0)) -> 0 | S7: =IF(R7=0,"Готово к передаче","Требует исправления") -> Готово к передаче | T7: =IF(R7=0,"",_xlfn.TEXTJOIN("; ",TRUE(),K7:Q7)) | U7: =IF(R7=0,"","Здравствуйте! В данных организации «"&B7&"» обнаружены ошибки: "&T7&". Просим проверить и прислать исправленную информацию.") | V7: =IF(R7>0,COUNTIF($R$2:R7,">0"),"") | W7: =IF(R7=0,COUNTIF($R$2:R7,0),"") -> 5
A8: 7 | B8: ООО «Квант Пласт» | C8: 6635202145 | D8: 1066607427677 | E8: 663543002 | F8: г. Екатеринбург, ул. Победы, д. 10, оф. 196 | G8: Волкова М. И. | H8: mail@kvant-plast.example | I8: 8 343 5123259 | J8: =IFERROR(VLOOKUP(VALUE(LEFT(C8,2)),Справочники!$A$2:$B$16,2,FALSE()),"не определён") -> Свердловская область | K8: =IF(TRIM(C8)="","ИНН не указан",IF(LEN(C8)<>10,"ИНН: должно быть 10 цифр",IF(NOT(ISNUMBER(IFERROR(VALUE(C8),"x"))),"ИНН: есть нецифровые символы",IF(MOD(MOD(SUMPRODUCT(--MID(C8,{1,2,3,4,5,6,7,8,9},1),{2,4,10,3,5,9,4,6,8}),11),10)=VALUE(RIGHT(C8,1)),"","ИНН: неверная контрольная цифра")))) | L8: =IF(TRIM(D8)="","ОГРН не указан",IF(LEN(D8)<>13,"ОГРН: должно быть 13 цифр",IF(NOT(ISNUMBER(IFERROR(VALUE(D8),"x"))),"ОГРН: есть нецифровые символы",IF(MOD(VALUE(LEFT(D8,12))-11*INT(VALUE(LEFT(D8,12))/11),10)=VALUE(RIGHT(D8,1)),"","ОГРН: неверная контрольная цифра")))) | M8: =IF(TRIM(E8)="","КПП не указан",IF(LEN(E8)<>9,"КПП: должно быть 9 знаков",IF(NOT(AND(ISNUMBER(IFERROR(VALUE(LEFT(E8,4)),"x")),ISNUMBER(IFERROR(VALUE(RIGHT(E8,3)),"x")))),"КПП: неверный формат",IF(LEFT(E8,2)<>LEFT(C8,2),"КПП: код региона не совпадает с ИНН","")))) | N8: =IF(TRIM(C8)="","",IF(COUNTIF($C$2:$C$401,C8)>1,"Дубликат ИНН в реестре","")) | O8: =IF(TRIM(H8)="","Email не указан",IF(AND(ISNUMBER(FIND("@",H8)),ISNUMBER(FIND(".",H8,IFERROR(FIND("@",H8),1))),ISERROR(FIND(" ",H8)),LEFT(H8,1)<>"@",RIGHT(H8,1)<>".",LEN(H8)-LEN(SUBSTITUTE(H8,"@",""))=1),"","Email: неверный формат")) | P8: =IF(TRIM(I8)="","Телефон не указан",IF(AND(LEN(SUBSTITUTE(SUBSTITUTE(SUBSTITUTE(SUBSTITUTE(SUBSTITUTE(I8," ",""),"-",""),"(",""),")",""),"+",""))=11,OR(LEFT(SUBSTITUTE(SUBSTITUTE(SUBSTITUTE(SUBSTITUTE(SUBSTITUTE(I8," ",""),"-",""),"(",""),")",""),"+",""),1)="7",LEFT(SUBSTITUTE(SUBSTITUTE(SUBSTITUTE(SUBSTITUTE(SUBSTITUTE(I8," ",""),"-",""),"(",""),")",""),"+",""),1)="8"),ISNUMBER(IFERROR(VALUE(SUBSTITUTE(SUBSTITUTE(SUBSTITUTE(SUBSTITUTE(SUBSTITUTE(I8," ",""),"-",""),"(",""),")",""),"+","")),"x"))),"","Телефон: неверный формат")) | Q8: =TRIM(IF(TRIM(B8)="","Нет наименования. ","")&IF(TRIM(F8)="","Нет адреса. ","")&IF(TRIM(G8)="","Нет контактного лица.","")) | R8: =SUMPRODUCT(--(LEN(K8:Q8)>0)) -> 0 | S8: =IF(R8=0,"Готово к передаче","Требует исправления") -> Готово к передаче | T8: =IF(R8=0,"",_xlfn.TEXTJOIN("; ",TRUE(),K8:Q8)) | U8: =IF(R8=0,"","Здравствуйте! В данных организации «"&B8&"» обнаружены ошибки: "&T8&". Просим проверить и прислать исправленную информацию.") | V8: =IF(R8>0,COUNTIF($R$2:R8,">0"),"") | W8: =IF(R8=0,COUNTIF($R$2:R8,0),"") -> 6
A9: 8 | B9: ООО «Вектор Проект» | C9: 6338452351 | D9: 1046306648563 | E9: 633801005 | F9: г. Самара, ул. Кирова, д. 29, оф. 87 | G9: Козлов С. Н. | H9: mail @ vektor-proekt.example | I9: +78465338368 | J9: =IFERROR(VLOOKUP(VALUE(LEFT(C9,2)),Справочники!$A$2:$B$16,2,FALSE()),"не определён") -> Самарская область | K9: =IF(TRIM(C9)="","ИНН не указан",IF(LEN(C9)<>10,"ИНН: должно быть 10 цифр",IF(NOT(ISNUMBER(IFERROR(VALUE(C9),"x"))),"ИНН: есть нецифровые символы",IF(MOD(MOD(SUMPRODUCT(--MID(C9,{1,2,3,4,5,6,7,8,9},1),{2,4,10,3,5,9,4,6,8}),11),10)=VALUE(RIGHT(C9,1)),"","ИНН: неверная контрольная цифра")))) -> ИНН: неверная контрольная цифра | L9: =IF(TRIM(D9)="","ОГРН не указан",IF(LEN(D9)<>13,"ОГРН: должно быть 13 цифр",IF(NOT(ISNUMBER(IFERROR(VALUE(D9),"x"))),"ОГРН: есть нецифровые символы",IF(MOD(VALUE(LEFT(D9,12))-11*INT(VALUE(LEFT(D9,12))/11),10)=VALUE(RIGHT(D9,1)),"","ОГРН: неверная контрольная цифра")))) | M9: =IF(TRIM(E9)="","КПП не указан",IF(LEN(E9)<>9,"КПП: должно быть 9 знаков",IF(NOT(AND(ISNUMBER(IFERROR(VALUE(LEFT(E9,4)),"x")),ISNUMBER(IFERROR(VALUE(RIGHT(E9,3)),"x")))),"КПП: неверный формат",IF(LEFT(E9,2)<>LEFT(C9,2),"КПП: код региона не совпадает с ИНН","")))) | N9: =IF(TRIM(C9)="","",IF(COUNTIF($C$2:$C$401,C9)>1,"Дубликат ИНН в реестре","")) | O9: =IF(TRIM(H9)="","Email не указан",IF(AND(ISNUMBER(FIND("@",H9)),ISNUMBER(FIND(".",H9,IFERROR(FIND("@",H9),1))),ISERROR(FIND(" ",H9)),LEFT(H9,1)<>"@",RIGHT(H9,1)<>".",LEN(H9)-LEN(SUBSTITUTE(H9,"@",""))=1),"","Email: неверный формат")) -> Email: неверный формат | P9: =IF(TRIM(I9)="","Телефон не указан",IF(AND(LEN(SUBSTITUTE(SUBSTITUTE(SUBSTITUTE(SUBSTITUTE(SUBSTITUTE(I9," ",""),"-",""),"(",""),")",""),"+",""))=11,OR(LEFT(SUBSTITUTE(SUBSTITUTE(SUBSTITUTE(SUBSTITUTE(SUBSTITUTE(I9," ",""),"-",""),"(",""),")",""),"+",""),1)="7",LEFT(SUBSTITUTE(SUBSTITUTE(SUBSTITUTE(SUBSTITUTE(SUBSTITUTE(I9," ",""),"-",""),"(",""),")",""),"+",""),1)="8"),ISNUMBER(IFERROR(VALUE(SUBSTITUTE(SUBSTITUTE(SUBSTITUTE(SUBSTITUTE(SUBSTITUTE(I9," ",""),"-",""),"(",""),")",""),"+","")),"x"))),"","Телефон: неверный формат")) | Q9: =TRIM(IF(TRIM(B9)="","Нет наименования. ","")&IF(TRIM(F9)="","Нет адреса. ","")&IF(TRIM(G9)="","Нет контактного лица.","")) | R9: =SUMPRODUCT(--(LEN(K9:Q9)>0)) -> 2 | S9: =IF(R9=0,"Готово к передаче","Требует исправления") -> Требует исправления | T9: =IF(R9=0,"",_xlfn.TEXTJOIN("; ",TRUE(),K9:Q9)) -> ИНН: неверная контрольная цифра; Email: неверный формат | U9: =IF(R9=0,"","Здравствуйте! В данных организации «"&B9&"» обнаружены ошибки: "&T9&". Просим проверить и прислать исправленную информацию.") -> Здравствуйте! В данных организации «ООО «Вектор Проект»» обнаружены ошибки: ИНН: неверная контрольная цифра; Email: неверный формат. Просим проверить и прислать исправленную информацию. | V9: =IF(R9>0,COUNTIF($R$2:R9,">0"),"") -> 2 | W9: =IF(R9=0,COUNTIF($R$2:R9,0),"")
A10: 9 | B10: АО «Гранит Снаб» | C10: 6615903294 | D10: 5136627773145 | E10: 661543004 | F10: г. Екатеринбург, ул. Советская, д. 57, оф. 291 | G10: Алексеева И. Н. | H10: office@granit-snab.example | I10: 8 343 5876238 | J10: =IFERROR(VLOOKUP(VALUE(LEFT(C10,2)),Справочники!$A$2:$B$16,2,FALSE()),"не определён") -> Свердловская область | K10: =IF(TRIM(C10)="","ИНН не указан",IF(LEN(C10)<>10,"ИНН: должно быть 10 цифр",IF(NOT(ISNUMBER(IFERROR(VALUE(C10),"x"))),"ИНН: есть нецифровые символы",IF(MOD(MOD(SUMPRODUCT(--MID(C10,{1,2,3,4,5,6,7,8,9},1),{2,4,10,3,5,9,4,6,8}),11),10)=VALUE(RIGHT(C10,1)),"","ИНН: неверная контрольная цифра")))) | L10: =IF(TRIM(D10)="","ОГРН не указан",IF(LEN(D10)<>13,"ОГРН: должно быть 13 цифр",IF(NOT(ISNUMBER(IFERROR(VALUE(D10),"x"))),"ОГРН: есть нецифровые символы",IF(MOD(VALUE(LEFT(D10,12))-11*INT(VALUE(LEFT(D10,12))/11),10)=VALUE(RIGHT(D10,1)),"","ОГРН: неверная контрольная цифра")))) | M10: =IF(TRIM(E10)="","КПП не указан",IF(LEN(E10)<>9,"КПП: должно быть 9 знаков",IF(NOT(AND(ISNUMBER(IFERROR(VALUE(LEFT(E10,4)),"x")),ISNUMBER(IFERROR(VALUE(RIGHT(E10,3)),"x")))),"КПП: неверный формат",IF(LEFT(E10,2)<>LEFT(C10,2),"КПП: код региона не совпадает с ИНН","")))) | N10: =IF(TRIM(C10)="","",IF(COUNTIF($C$2:$C$401,C10)>1,"Дубликат ИНН в реестре","")) | O10: =IF(TRIM(H10)="","Email не указан",IF(AND(ISNUMBER(FIND("@",H10)),ISNUMBER(FIND(".",H10,IFERROR(FIND("@",H10),1))),ISERROR(FIND(" ",H10)),LEFT(H10,1)<>"@",RIGHT(H10,1)<>".",LEN(H10)-LEN(SUBSTITUTE(H10,"@",""))=1),"","Email: неверный формат")) | P10: =IF(TRIM(I10)="","Телефон не указан",IF(AND(LEN(SUBSTITUTE(SUBSTITUTE(SUBSTITUTE(SUBSTITUTE(SUBSTITUTE(I10," ",""),"-",""),"(",""),")",""),"+",""))=11,OR(LEFT(SUBSTITUTE(SUBSTITUTE(SUBSTITUTE(SUBSTITUTE(SUBSTITUTE(I10," ",""),"-",""),"(",""),")",""),"+",""),1)="7",LEFT(SUBSTITUTE(SUBSTITUTE(SUBSTITUTE(SUBSTITUTE(SUBSTITUTE(I10," ",""),"-",""),"(",""),")",""),"+",""),1)="8"),ISNUMBER(IFERROR(VALUE(SUBSTITUTE(SUBSTITUTE(SUBSTITUTE(SUBSTITUTE(SUBSTITUTE(I10," ",""),"-",""),"(",""),")",""),"+","")),"x"))),"","Телефон: неверный формат")) | Q10: =TRIM(IF(TRIM(B10)="","Нет наименования. ","")&IF(TRIM(F10)="","Нет адреса. ","")&IF(TRIM(G10)="","Нет контактного лица.","")) | R10: =SUMPRODUCT(--(LEN(K10:Q10)>0)) -> 0 | S10: =IF(R10=0,"Готово к передаче","Требует исправления") -> Готово к передаче | T10: =IF(R10=0,"",_xlfn.TEXTJOIN("; ",TRUE(),K10:Q10)) | U10: =IF(R10=0,"","Здравствуйте! В данных организации «"&B10&"» обнаружены ошибки: "&T10&". Просим проверить и прислать исправленную информацию.") | V10: =IF(R10>0,COUNTIF($R$2:R10,">0"),"") | W10: =IF(R10=0,COUNTIF($R$2:R10,0),"") -> 7
A11: 10 | B11: АО «Эталон Проект» | C11: 782218804 | D11: 1107819752864 | E11: 782243007 | F11: г. Санкт-Петербург, ул. Садовая, д. 3, оф. 282 | G11: Новикова М. И. | H11: mail@etalon-proekt.example | I11: 8 812 5099621 | J11: =IFERROR(VLOOKUP(VALUE(LEFT(C11,2)),Справочники!$A$2:$B$16,2,FALSE()),"не определён") -> г. Санкт-Петербург | K11: =IF(TRIM(C11)="","ИНН не указан",IF(LEN(C11)<>10,"ИНН: должно быть 10 цифр",IF(NOT(ISNUMBER(IFERROR(VALUE(C11),"x"))),"ИНН: есть нецифровые символы",IF(MOD(MOD(SUMPRODUCT(--MID(C11,{1,2,3,4,5,6,7,8,9},1),{2,4,10,3,5,9,4,6,8}),11),10)=VALUE(RIGHT(C11,1)),"","ИНН: неверная контрольная цифра")))) -> ИНН: должно быть 10 цифр | L11: =IF(TRIM(D11)="","ОГРН не указан",IF(LEN(D11)<>13,"ОГРН: должно быть 13 цифр",IF(NOT(ISNUMBER(IFERROR(VALUE(D11),"x"))),"ОГРН: есть нецифровые символы",IF(MOD(VALUE(LEFT(D11,12))-11*INT(VALUE(LEFT(D11,12))/11),10)=VALUE(RIGHT(D11,1)),"","ОГРН: неверная контрольная цифра")))) | M11: =IF(TRIM(E11)="","КПП не указан",IF(LEN(E11)<>9,"КПП: должно быть 9 знаков",IF(NOT(AND(ISNUMBER(IFERROR(VALUE(LEFT(E11,4)),"x")),ISNUMBER(IFERROR(VALUE(RIGHT(E11,3)),"x")))),"КПП: неверный формат",IF(LEFT(E11,2)<>LEFT(C11,2),"КПП: код региона не совпадает с ИНН","")))) | N11: =IF(TRIM(C11)="","",IF(COUNTIF($C$2:$C$401,C11)>1,"Дубликат ИНН в реестре","")) | O11: =IF(TRIM(H11)="","Email не указан",IF(AND(ISNUMBER(FIND("@",H11)),ISNUMBER(FIND(".",H11,IFERROR(FIND("@",H11),1))),ISERROR(FIND(" ",H11)),LEFT(H11,1)<>"@",RIGHT(H11,1)<>".",LEN(H11)-LEN(SUBSTITUTE(H11,"@",""))=1),"","Email: неверный формат")) | P11: =IF(TRIM(I11)="","Телефон не указан",IF(AND(LEN(SUBSTITUTE(SUBSTITUTE(SUBSTITUTE(SUBSTITUTE(SUBSTITUTE(I11," ",""),"-",""),"(",""),")",""),"+",""))=11,OR(LEFT(SUBSTITUTE(SUBSTITUTE(SUBSTITUTE(SUBSTITUTE(SUBSTITUTE(I11," ",""),"-",""),"(",""),")",""),"+",""),1)="7",LEFT(SUBSTITUTE(SUBSTITUTE(SUBSTITUTE(SUBSTITUTE(SUBSTITUTE(I11," ",""),"-",""),"(",""),")",""),"+",""),1)="8"),ISNUMBER(IFERROR(VALUE(SUBSTITUTE(SUBSTITUTE(SUBSTITUTE(SUBSTITUTE(SUBSTITUTE(I11," ",""),"-",""),"(",""),")",""),"+","")),"x"))),"","Телефон: неверный формат")) | Q11: =TRIM(IF(TRIM(B11)="","Нет наименования. ","")&IF(TRIM(F11)="","Нет адреса. ","")&IF(TRIM(G11)="","Нет контактного лица.","")) | R11: =SUMPRODUCT(--(LEN(K11:Q11)>0)) -> 1 | S11: =IF(R11=0,"Готово к передаче","Требует исправления") -> Требует исправления | T11: =IF(R11=0,"",_xlfn.TEXTJOIN("; ",TRUE(),K11:Q11)) -> ИНН: должно быть 10 цифр | U11: =IF(R11=0,"","Здравствуйте! В данных организации «"&B11&"» обнаружены ошибки: "&T11&". Просим проверить и прислать исправленную информацию.") -> Здравствуйте! В данных организации «АО «Эталон Проект»» обнаружены ошибки: ИНН: должно быть 10 цифр. Просим проверить и прислать исправленную информацию. | V11: =IF(R11>0,COUNTIF($R$2:R11,">0"),"") -> 3 | W11: =IF(R11=0,COUNTIF($R$2:R11,0),"")
A12: 11 | B12: ООО «Гранит Агро» | C12: 6326949532 | D12: 1026318732582 | E12: 632601003 | F12: г. Самара, ул. Центральная, д. 75, оф. 213 | G12: Лебедева С. А. | H12: zakaz@granit-agro.example | I12: +7 (846) 561-53-11 | J12: =IFERROR(VLOOKUP(VALUE(LEFT(C12,2)),Справочники!$A$2:$B$16,2,FALSE()),"не определён") -> Самарская область | K12: =IF(TRIM(C12)="","ИНН не указан",IF(LEN(C12)<>10,"ИНН: должно быть 10 цифр",IF(NOT(ISNUMBER(IFERROR(VALUE(C12),"x"))),"ИНН: есть нецифровые символы",IF(MOD(MOD(SUMPRODUCT(--MID(C12,{1,2,3,4,5,6,7,8,9},1),{2,4,10,3,5,9,4,6,8}),11),10)=VALUE(RIGHT(C12,1)),"","ИНН: неверная контрольная цифра")))) | L12: =IF(TRIM(D12)="","ОГРН не указан",IF(LEN(D12)<>13,"ОГРН: должно быть 13 цифр",IF(NOT(ISNUMBER(IFERROR(VALUE(D12),"x"))),"ОГРН: есть нецифровые символы",IF(MOD(VALUE(LEFT(D12,12))-11*INT(VALUE(LEFT(D12,12))/11),10)=VALUE(RIGHT(D12,1)),"","ОГРН: неверная контрольная цифра")))) | M12: =IF(TRIM(E12)="","КПП не указан",IF(LEN(E12)<>9,"КПП: должно быть 9 знаков",IF(NOT(AND(ISNUMBER(IFERROR(VALUE(LEFT(E12,4)),"x")),ISNUMBER(IFERROR(VALUE(RIGHT(E12,3)),"x")))),"КПП: неверный формат",IF(LEFT(E12,2)<>LEFT(C12,2),"КПП: код региона не совпадает с ИНН","")))) | N12: =IF(TRIM(C12)="","",IF(COUNTIF($C$2:$C$401,C12)>1,"Дубликат ИНН в реестре","")) | O12: =IF(TRIM(H12)="","Email не указан",IF(AND(ISNUMBER(FIND("@",H12)),ISNUMBER(FIND(".",H12,IFERROR(FIND("@",H12),1))),ISERROR(FIND(" ",H12)),LEFT(H12,1)<>"@",RIGHT(H12,1)<>".",LEN(H12)-LEN(SUBSTITUTE(H12,"@",""))=1),"","Email: неверный формат")) | P12: =IF(TRIM(I12)="","Телефон не указан",IF(AND(LEN(SUBSTITUTE(SUBSTITUTE(SUBSTITUTE(SUBSTITUTE(SUBSTITUTE(I12," ",""),"-",""),"(",""),")",""),"+",""))=11,OR(LEFT(SUBSTITUTE(SUBSTITUTE(SUBSTITUTE(SUBSTITUTE(SUBSTITUTE(I12," ",""),"-",""),"(",""),")",""),"+",""),1)="7",LEFT(SUBSTITUTE(SUBSTITUTE(SUBSTITUTE(SUBSTITUTE(SUBSTITUTE(I12," ",""),"-",""),"(",""),")",""),"+",""),1)="8"),ISNUMBER(IFERROR(VALUE(SUBSTITUTE(SUBSTITUTE(SUBSTITUTE(SUBSTITUTE(SUBSTITUTE(I12," ",""),"-",""),"(",""),")",""),"+","")),"x"))),"","Телефон: неверный формат")) | Q12: =TRIM(IF(TRIM(B12)="","Нет наименования. ","")&IF(TRIM(F12)="","Нет адреса. ","")&IF(TRIM(G12)="","Нет контактного лица.","")) | R12: =SUMPRODUCT(--(LEN(K12:Q12)>0)) -> 0 | S12: =IF(R12=0,"Готово к передаче","Требует исправления") -> Готово к передаче | T12: =IF(R12=0,"",_xlfn.TEXTJOIN("; ",TRUE(),K12:Q12)) | U12: =IF(R12=0,"","Здравствуйте! В данных организации «"&B12&"» обнаружены ошибки: "&T12&". Просим проверить и прислать исправленную информацию.") | V12: =IF(R12>0,COUNTIF($R$2:R12,">0"),"") | W12: =IF(R12=0,COUNTIF($R$2:R12,0),"") -> 8
A13: 12 | B13: ООО «Эталон Технологии» | C13: 1633362955 | D13: 5041636907582 | E13: 163301009 | F13: г. Казань, ул. Ленина, д. 13, оф. 80 | G13: Морозова И. Н. | H13: mail @ etalon-tekhnologii.example | I13: +7 (843) 528-69-36 | J13: =IFERROR(VLOOKUP(VALUE(LEFT(C13,2)),Справочники!$A$2:$B$16,2,FALSE()),"не определён") -> Республика Татарстан | K13: =IF(TRIM(C13)="","ИНН не указан",IF(LEN(C13)<>10,"ИНН: должно быть 10 цифр",IF(NOT(ISNUMBER(IFERROR(VALUE(C13),"x"))),"ИНН: есть нецифровые символы",IF(MOD(MOD(SUMPRODUCT(--MID(C13,{1,2,3,4,5,6,7,8,9},1),{2,4,10,3,5,9,4,6,8}),11),10)=VALUE(RIGHT(C13,1)),"","ИНН: неверная контрольная цифра")))) | L13: =IF(TRIM(D13)="","ОГРН не указан",IF(LEN(D13)<>13,"ОГРН: должно быть 13 цифр",IF(NOT(ISNUMBER(IFERROR(VALUE(D13),"x"))),"ОГРН: есть нецифровые символы",IF(MOD(VALUE(LEFT(D13,12))-11*INT(VALUE(LEFT(D13,12))/11),10)=VALUE(RIGHT(D13,1)),"","ОГРН: неверная контрольная цифра")))) | M13: =IF(TRIM(E13)="","КПП не указан",IF(LEN(E13)<>9,"КПП: должно быть 9 знаков",IF(NOT(AND(ISNUMBER(IFERROR(VALUE(LEFT(E13,4)),"x")),ISNUMBER(IFERROR(VALUE(RIGHT(E13,3)),"x")))),"КПП: неверный формат",IF(LEFT(E13,2)<>LEFT(C13,2),"КПП: код региона не совпадает с ИНН","")))) | N13: =IF(TRIM(C13)="","",IF(COUNTIF($C$2:$C$401,C13)>1,"Дубликат ИНН в реестре","")) | O13: =IF(TRIM(H13)="","Email не указан",IF(AND(ISNUMBER(FIND("@",H13)),ISNUMBER(FIND(".",H13,IFERROR(FIND("@",H13),1))),ISERROR(FIND(" ",H13)),LEFT(H13,1)<>"@",RIGHT(H13,1)<>".",LEN(H13)-LEN(SUBSTITUTE(H13,"@",""))=1),"","Email: неверный формат")) -> Email: неверный формат | P13: =IF(TRIM(I13)="","Телефон не указан",IF(AND(LEN(SUBSTITUTE(SUBSTITUTE(SUBSTITUTE(SUBSTITUTE(SUBSTITUTE(I13," ",""),"-",""),"(",""),")",""),"+",""))=11,OR(LEFT(SUBSTITUTE(SUBSTITUTE(SUBSTITUTE(SUBSTITUTE(SUBSTITUTE(I13," ",""),"-",""),"(",""),")",""),"+",""),1)="7",LEFT(SUBSTITUTE(SUBSTITUTE(SUBSTITUTE(SUBSTITUTE(SUBSTITUTE(I13," ",""),"-",""),"(",""),")",""),"+",""),1)="8"),ISNUMBER(IFERROR(VALUE(SUBSTITUTE(SUBSTITUTE(SUBSTITUTE(SUBSTITUTE(SUBSTITUTE(I13," ",""),"-",""),"(",""),")",""),"+","")),"x"))),"","Телефон: неверный формат")) | Q13: =TRIM(IF(TRIM(B13)="","Нет наименования. ","")&IF(TRIM(F13)="","Нет адреса. ","")&IF(TRIM(G13)="","Нет контактного лица.","")) | R13: =SUMPRODUCT(--(LEN(K13:Q13)>0)) -> 1 | S13: =IF(R13=0,"Готово к передаче","Требует исправления") -> Требует исправления | T13: =IF(R13=0,"",_xlfn.TEXTJOIN("; ",TRUE(),K13:Q13)) -> Email: неверный формат | U13: =IF(R13=0,"","Здравствуйте! В данных организации «"&B13&"» обнаружены ошибки: "&T13&". Просим проверить и прислать исправленную информацию.") -> Здравствуйте! В данных организации «ООО «Эталон Технологии»» обнаружены ошибки: Email: неверный формат. Просим проверить и прислать исправленную информацию. | V13: =IF(R13>0,COUNTIF($R$2:R13,">0"),"") -> 4 | W13: =IF(R13=0,COUNTIF($R$2:R13,0),"")
A14: 13 | B14: ООО «Дельта Технологии» | C14: 5436174653 | D14: 1025418549892 | E14: 54360100 | F14: г. Новосибирск, ул. Набережная, д. 94, оф. 263 | G14: Степанова В. Т. | H14: office@delta-tekhnologii.example | I14: 8 383 5357843 | J14: =IFERROR(VLOOKUP(VALUE(LEFT(C14,2)),Справочники!$A$2:$B$16,2,FALSE()),"не определён") -> Новосибирская область | K14: =IF(TRIM(C14)="","ИНН не указан",IF(LEN(C14)<>10,"ИНН: должно быть 10 цифр",IF(NOT(ISNUMBER(IFERROR(VALUE(C14),"x"))),"ИНН: есть нецифровые символы",IF(MOD(MOD(SUMPRODUCT(--MID(C14,{1,2,3,4,5,6,7,8,9},1),{2,4,10,3,5,9,4,6,8}),11),10)=VALUE(RIGHT(C14,1)),"","ИНН: неверная контрольная цифра")))) | L14: =IF(TRIM(D14)="","ОГРН не указан",IF(LEN(D14)<>13,"ОГРН: должно быть 13 цифр",IF(NOT(ISNUMBER(IFERROR(VALUE(D14),"x"))),"ОГРН: есть нецифровые символы",IF(MOD(VALUE(LEFT(D14,12))-11*INT(VALUE(LEFT(D14,12))/11),10)=VALUE(RIGHT(D14,1)),"","ОГРН: неверная контрольная цифра")))) | M14: =IF(TRIM(E14)="","КПП не указан",IF(LEN(E14)<>9,"КПП: должно быть 9 знаков",IF(NOT(AND(ISNUMBER(IFERROR(VALUE(LEFT(E14,4)),"x")),ISNUMBER(IFERROR(VALUE(RIGHT(E14,3)),"x")))),"КПП: неверный формат",IF(LEFT(E14,2)<>LEFT(C14,2),"КПП: код региона не совпадает с ИНН","")))) -> КПП: должно быть 9 знаков | N14: =IF(TRIM(C14)="","",IF(COUNTIF($C$2:$C$401,C14)>1,"Дубликат ИНН в реестре","")) | O14: =IF(TRIM(H14)="","Email не указан",IF(AND(ISNUMBER(FIND("@",H14)),ISNUMBER(FIND(".",H14,IFERROR(FIND("@",H14),1))),ISERROR(FIND(" ",H14)),LEFT(H14,1)<>"@",RIGHT(H14,1)<>".",LEN(H14)-LEN(SUBSTITUTE(H14,"@",""))=1),"","Email: неверный формат")) | P14: =IF(TRIM(I14)="","Телефон не указан",IF(AND(LEN(SUBSTITUTE(SUBSTITUTE(SUBSTITUTE(SUBSTITUTE(SUBSTITUTE(I14," ",""),"-",""),"(",""),")",""),"+",""))=11,OR(LEFT(SUBSTITUTE(SUBSTITUTE(SUBSTITUTE(SUBSTITUTE(SUBSTITUTE(I14," ",""),"-",""),"(",""),")",""),"+",""),1)="7",LEFT(SUBSTITUTE(SUBSTITUTE(SUBSTITUTE(SUBSTITUTE(SUBSTITUTE(I14," ",""),"-",""),"(",""),")",""),"+",""),1)="8"),ISNUMBER(IFERROR(VALUE(SUBSTITUTE(SUBSTITUTE(SUBSTITUTE(SUBSTITUTE(SUBSTITUTE(I14," ",""),"-",""),"(",""),")",""),"+","")),"x"))),"","Телефон: неверный формат")) | Q14: =TRIM(IF(TRIM(B14)="","Нет наименования. ","")&IF(TRIM(F14)="","Нет адреса. ","")&IF(TRIM(G14)="","Нет контактного лица.","")) | R14: =SUMPRODUCT(--(LEN(K14:Q14)>0)) -> 1 | S14: =IF(R14=0,"Готово к передаче","Требует исправления") -> Требует исправления | T14: =IF(R14=0,"",_xlfn.TEXTJOIN("; ",TRUE(),K14:Q14)) -> КПП: должно быть 9 знаков | U14: =IF(R14=0,"","Здравствуйте! В данных организации «"&B14&"» обнаружены ошибки: "&T14&". Просим проверить и прислать исправленную информацию.") -> Здравствуйте! В данных организации «ООО «Дельта Технологии»» обнаружены ошибки: КПП: должно быть 9 знаков. Просим проверить и прислать исправленную информацию. | V14: =IF(R14>0,COUNTIF($R$2:R14,">0"),"") -> 5 | W14: =IF(R14=0,COUNTIF($R$2:R14,0),"")
A15: 14 | B15: АО «Вектор Групп» | C15: 9203843570 | D15: 5069202630030 | E15: 920301005 | F15: г. Севастополь, ул. Заводская, д. 26, оф. 189 | G15: Новикова С. М. | H15: mail@vektor-grupp.example | J15: =IFERROR(VLOOKUP(VALUE(LEFT(C15,2)),Справочники!$A$2:$B$16,2,FALSE()),"не определён") -> г. Севастополь | K15: =IF(TRIM(C15)="","ИНН не указан",IF(LEN(C15)<>10,"ИНН: должно быть 10 цифр",IF(NOT(ISNUMBER(IFERROR(VALUE(C15),"x"))),"ИНН: есть нецифровые символы",IF(MOD(MOD(SUMPRODUCT(--MID(C15,{1,2,3,4,5,6,7,8,9},1),{2,4,10,3,5,9,4,6,8}),11),10)=VALUE(RIGHT(C15,1)),"","ИНН: неверная контрольная цифра")))) | L15: =IF(TRIM(D15)="","ОГРН не указан",IF(LEN(D15)<>13,"ОГРН: должно быть 13 цифр",IF(NOT(ISNUMBER(IFERROR(VALUE(D15),"x"))),"ОГРН: есть нецифровые символы",IF(MOD(VALUE(LEFT(D15,12))-11*INT(VALUE(LEFT(D15,12))/11),10)=VALUE(RIGHT(D15,1)),"","ОГРН: неверная контрольная цифра")))) | M15: =IF(TRIM(E15)="","КПП не указан",IF(LEN(E15)<>9,"КПП: должно быть 9 знаков",IF(NOT(AND(ISNUMBER(IFERROR(VALUE(LEFT(E15,4)),"x")),ISNUMBER(IFERROR(VALUE(RIGHT(E15,3)),"x")))),"КПП: неверный формат",IF(LEFT(E15,2)<>LEFT(C15,2),"КПП: код региона не совпадает с ИНН","")))) | N15: =IF(TRIM(C15)="","",IF(COUNTIF($C$2:$C$401,C15)>1,"Дубликат ИНН в реестре","")) | O15: =IF(TRIM(H15)="","Email не указан",IF(AND(ISNUMBER(FIND("@",H15)),ISNUMBER(FIND(".",H15,IFERROR(FIND("@",H15),1))),ISERROR(FIND(" ",H15)),LEFT(H15,1)<>"@",RIGHT(H15,1)<>".",LEN(H15)-LEN(SUBSTITUTE(H15,"@",""))=1),"","Email: неверный формат")) | P15: =IF(TRIM(I15)="","Телефон не указан",IF(AND(LEN(SUBSTITUTE(SUBSTITUTE(SUBSTITUTE(SUBSTITUTE(SUBSTITUTE(I15," ",""),"-",""),"(",""),")",""),"+",""))=11,OR(LEFT(SUBSTITUTE(SUBSTITUTE(SUBSTITUTE(SUBSTITUTE(SUBSTITUTE(I15," ",""),"-",""),"(",""),")",""),"+",""),1)="7",LEFT(SUBSTITUTE(SUBSTITUTE(SUBSTITUTE(SUBSTITUTE(SUBSTITUTE(I15," ",""),"-",""),"(",""),")",""),"+",""),1)="8"),ISNUMBER(IFERROR(VALUE(SUBSTITUTE(SUBSTITUTE(SUBSTITUTE(SUBSTITUTE(SUBSTITUTE(I15," ",""),"-",""),"(",""),")",""),"+","")),"x"))),"","Телефон: неверный формат")) -> Телефон не указан | Q15: =TRIM(IF(TRIM(B15)="","Нет наименования. ","")&IF(TRIM(F15)="","Нет адреса. ","")&IF(TRIM(G15)="","Нет контактного лица.","")) | R15: =SUMPRODUCT(--(LEN(K15:Q15)>0)) -> 1 | S15: =IF(R15=0,"Готово к передаче","Требует исправления") -> Требует исправления | T15: =IF(R15=0,"",_xlfn.TEXTJOIN("; ",TRUE(),K15:Q15)) -> Телефон не указан | U15: =IF(R15=0,"","Здравствуйте! В данных организации «"&B15&"» обнаружены ошибки: "&T15&". Просим проверить и прислать исправленную информацию.") -> Здравствуйте! В данных организации «АО «Вектор Групп»» обнаружены ошибки: Телефон не указан. Просим проверить и прислать исправленную информацию. | V15: =IF(R15>0,COUNTIF($R$2:R15,">0"),"") -> 6 | W15: =IF(R15=0,COUNTIF($R$2:R15,0),"")
A16: 15 | B16: ООО «Эталон Энерго» | C16: 6140118904 | D16: 5176121865805 | E16: 614001006 | F16: г. Ростов-на-Дону, ул. Советская, д. 10, оф. 288 | G16: Павлов М. Н. | H16: office@etalon-energo.example | I16: 8 863 5545828 | J16: =IFERROR(VLOOKUP(VALUE(LEFT(C16,2)),Справочники!$A$2:$B$16,2,FALSE()),"не определён") -> Ростовская область | K16: =IF(TRIM(C16)="","ИНН не указан",IF(LEN(C16)<>10,"ИНН: должно быть 10 цифр",IF(NOT(ISNUMBER(IFERROR(VALUE(C16),"x"))),"ИНН: есть нецифровые символы",IF(MOD(MOD(SUMPRODUCT(--MID(C16,{1,2,3,4,5,6,7,8,9},1),{2,4,10,3,5,9,4,6,8}),11),10)=VALUE(RIGHT(C16,1)),"","ИНН: неверная контрольная цифра")))) -> ИНН: неверная контрольная цифра | L16: =IF(TRIM(D16)="","ОГРН не указан",IF(LEN(D16)<>13,"ОГРН: должно быть 13 цифр",IF(NOT(ISNUMBER(IFERROR(VALUE(D16),"x"))),"ОГРН: есть нецифровые символы",IF(MOD(VALUE(LEFT(D16,12))-11*INT(VALUE(LEFT(D16,12))/11),10)=VALUE(RIGHT(D16,1)),"","ОГРН: неверная контрольная цифра")))) | M16: =IF(TRIM(E16)="","КПП не указан",IF(LEN(E16)<>9,"КПП: должно быть 9 знаков",IF(NOT(AND(ISNUMBER(IFERROR(VALUE(LEFT(E16,4)),"x")),ISNUMBER(IFERROR(VALUE(RIGHT(E16,3)),"x")))),"КПП: неверный формат",IF(LEFT(E16,2)<>LEFT(C16,2),"КПП: код региона не совпадает с ИНН","")))) | N16: =IF(TRIM(C16)="","",IF(COUNTIF($C$2:$C$401,C16)>1,"Дубликат ИНН в реестре","")) | O16: =IF(TRIM(H16)="","Email не указан",IF(AND(ISNUMBER(FIND("@",H16)),ISNUMBER(FIND(".",H16,IFERROR(FIND("@",H16),1))),ISERROR(FIND(" ",H16)),LEFT(H16,1)<>"@",RIGHT(H16,1)<>".",LEN(H16)-LEN(SUBSTITUTE(H16,"@",""))=1),"","Email: неверный формат")) | P16: =IF(TRIM(I16)="","Телефон не указан",IF(AND(LEN(SUBSTITUTE(SUBSTITUTE(SUBSTITUTE(SUBSTITUTE(SUBSTITUTE(I16," ",""),"-",""),"(",""),")",""),"+",""))=11,OR(LEFT(SUBSTITUTE(SUBSTITUTE(SUBSTITUTE(SUBSTITUTE(SUBSTITUTE(I16," ",""),"-",""),"(",""),")",""),"+",""),1)="7",LEFT(SUBSTITUTE(SUBSTITUTE(SUBSTITUTE(SUBSTITUTE(SUBSTITUTE(I16," ",""),"-",""),"(",""),")",""),"+",""),1)="8"),ISNUMBER(IFERROR(VALUE(SUBSTITUTE(SUBSTITUTE(SUBSTITUTE(SUBSTITUTE(SUBSTITUTE(I16," ",""),"-",""),"(",""),")",""),"+","")),"x"))),"","Телефон: неверный формат")) | Q16: =TRIM(IF(TRIM(B16)="","Нет наименования. ","")&IF(TRIM(F16)="","Нет адреса. ","")&IF(TRIM(G16)="","Нет контактного лица.","")) | R16: =SUMPRODUCT(--(LEN(K16:Q16)>0)) -> 1 | S16: =IF(R16=0,"Готово к передаче","Требует исправления") -> Требует исправления | T16: =IF(R16=0,"",_xlfn.TEXTJOIN("; ",TRUE(),K16:Q16)) -> ИНН: неверная контрольная цифра | U16: =IF(R16=0,"","Здравствуйте! В данных организации «"&B16&"» обнаружены ошибки: "&T16&". Просим проверить и прислать исправленную информацию.") -> Здравствуйте! В данных организации «ООО «Эталон Энерго»» обнаружены ошибки: ИНН: неверная контрольная цифра. Просим проверить и прислать исправленную информацию. | V16: =IF(R16>0,COUNTIF($R$2:R16,">0"),"") -> 7 | W16: =IF(R16=0,COUNTIF($R$2:R16,0),"")
A17: 16 | B17: ООО «Навигатор Сервис» | C17: 1633690191 | D17: 1181614354789 | E17: 163343003 | F17: г. Казань, ул. Набережная, д. 87, оф. 167 | G17: Иванова И. О. | H17: mail@navigator-servis.example | I17: +78435761425 | J17: =IFERROR(VLOOKUP(VALUE(LEFT(C17,2)),Справочники!$A$2:$B$16,2,FALSE()),"не определён") -> Республика Татарстан | K17: =IF(TRIM(C17)="","ИНН не указан",IF(LEN(C17)<>10,"ИНН: должно быть 10 цифр",IF(NOT(ISNUMBER(IFERROR(VALUE(C17),"x"))),"ИНН: есть нецифровые символы",IF(MOD(MOD(SUMPRODUCT(--MID(C17,{1,2,3,4,5,6,7,8,9},1),{2,4,10,3,5,9,4,6,8}),11),10)=VALUE(RIGHT(C17,1)),"","ИНН: неверная контрольная цифра")))) | L17: =IF(TRIM(D17)="","ОГРН не указан",IF(LEN(D17)<>13,"ОГРН: должно быть 13 цифр",IF(NOT(ISNUMBER(IFERROR(VALUE(D17),"x"))),"ОГРН: есть нецифровые символы",IF(MOD(VALUE(LEFT(D17,12))-11*INT(VALUE(LEFT(D17,12))/11),10)=VALUE(RIGHT(D17,1)),"","ОГРН: неверная контрольная цифра")))) | M17: =IF(TRIM(E17)="","КПП не указан",IF(LEN(E17)<>9,"КПП: должно быть 9 знаков",IF(NOT(AND(ISNUMBER(IFERROR(VALUE(LEFT(E17,4)),"x")),ISNUMBER(IFERROR(VALUE(RIGHT(E17,3)),"x")))),"КПП: неверный формат",IF(LEFT(E17,2)<>LEFT(C17,2),"КПП: код региона не совпадает с ИНН","")))) | N17: =IF(TRIM(C17)="","",IF(COUNTIF($C$2:$C$401,C17)>1,"Дубликат ИНН в реестре","")) | O17: =IF(TRIM(H17)="","Email не указан",IF(AND(ISNUMBER(FIND("@",H17)),ISNUMBER(FIND(".",H17,IFERROR(FIND("@",H17),1))),ISERROR(FIND(" ",H17)),LEFT(H17,1)<>"@",RIGHT(H17,1)<>".",LEN(H17)-LEN(SUBSTITUTE(H17,"@",""))=1),"","Email: неверный формат")) | P17: =IF(TRIM(I17)="","Телефон не указан",IF(AND(LEN(SUBSTITUTE(SUBSTITUTE(SUBSTITUTE(SUBSTITUTE(SUBSTITUTE(I17," ",""),"-",""),"(",""),")",""),"+",""))=11,OR(LEFT(SUBSTITUTE(SUBSTITUTE(SUBSTITUTE(SUBSTITUTE(SUBSTITUTE(I17," ",""),"-",""),"(",""),")",""),"+",""),1)="7",LEFT(SUBSTITUTE(SUBSTITUTE(SUBSTITUTE(SUBSTITUTE(SUBSTITUTE(I17," ",""),"-",""),"(",""),")",""),"+",""),1)="8"),ISNUMBER(IFERROR(VALUE(SUBSTITUTE(SUBSTITUTE(SUBSTITUTE(SUBSTITUTE(SUBSTITUTE(I17," ",""),"-",""),"(",""),")",""),"+","")),"x"))),"","Телефон: неверный формат")) | Q17: =TRIM(IF(TRIM(B17)="","Нет наименования. ","")&IF(TRIM(F17)="","Нет адреса. ","")&IF(TRIM(G17)="","Нет контактного лица.","")) | R17: =SUMPRODUCT(--(LEN(K17:Q17)>0)) -> 0 | S17: =IF(R17=0,"Готово к передаче","Требует исправления") -> Готово к передаче | T17: =IF(R17=0,"",_xlfn.TEXTJOIN("; ",TRUE(),K17:Q17)) | U17: =IF(R17=0,"","Здравствуйте! В данных организации «"&B17&"» обнаружены ошибки: "&T17&". Просим проверить и прислать исправленную информацию.") | V17: =IF(R17>0,COUNTIF($R$2:R17,">0"),"") | W17: =IF(R17=0,COUNTIF($R$2:R17,0),"") -> 9
A18: 17 | B18: ООО «Импульс Фуд» | C18: 7843045О55 | D18: 5117812182439 | E18: 784301009 | F18: г. Санкт-Петербург, ул. Победы, д. 46, оф. 66 | G18: Попова Т. А. | H18: zakaz@impuls-fud.example | I18: +7 (812) 521-33-98 | J18: =IFERROR(VLOOKUP(VALUE(LEFT(C18,2)),Справочники!$A$2:$B$16,2,FALSE()),"не определён") -> г. Санкт-Петербург | K18: =IF(TRIM(C18)="","ИНН не указан",IF(LEN(C18)<>10,"ИНН: должно быть 10 цифр",IF(NOT(ISNUMBER(IFERROR(VALUE(C18),"x"))),"ИНН: есть нецифровые символы",IF(MOD(MOD(SUMPRODUCT(--MID(C18,{1,2,3,4,5,6,7,8,9},1),{2,4,10,3,5,9,4,6,8}),11),10)=VALUE(RIGHT(C18,1)),"","ИНН: неверная контрольная цифра")))) -> ИНН: есть нецифровые символы | L18: =IF(TRIM(D18)="","ОГРН не указан",IF(LEN(D18)<>13,"ОГРН: должно быть 13 цифр",IF(NOT(ISNUMBER(IFERROR(VALUE(D18),"x"))),"ОГРН: есть нецифровые символы",IF(MOD(VALUE(LEFT(D18,12))-11*INT(VALUE(LEFT(D18,12))/11),10)=VALUE(RIGHT(D18,1)),"","ОГРН: неверная контрольная цифра")))) | M18: =IF(TRIM(E18)="","КПП не указан",IF(LEN(E18)<>9,"КПП: должно быть 9 знаков",IF(NOT(AND(ISNUMBER(IFERROR(VALUE(LEFT(E18,4)),"x")),ISNUMBER(IFERROR(VALUE(RIGHT(E18,3)),"x")))),"КПП: неверный формат",IF(LEFT(E18,2)<>LEFT(C18,2),"КПП: код региона не совпадает с ИНН","")))) | N18: =IF(TRIM(C18)="","",IF(COUNTIF($C$2:$C$401,C18)>1,"Дубликат ИНН в реестре","")) | O18: =IF(TRIM(H18)="","Email не указан",IF(AND(ISNUMBER(FIND("@",H18)),ISNUMBER(FIND(".",H18,IFERROR(FIND("@",H18),1))),ISERROR(FIND(" ",H18)),LEFT(H18,1)<>"@",RIGHT(H18,1)<>".",LEN(H18)-LEN(SUBSTITUTE(H18,"@",""))=1),"","Email: неверный формат")) | P18: =IF(TRIM(I18)="","Телефон не указан",IF(AND(LEN(SUBSTITUTE(SUBSTITUTE(SUBSTITUTE(SUBSTITUTE(SUBSTITUTE(I18," ",""),"-",""),"(",""),")",""),"+",""))=11,OR(LEFT(SUBSTITUTE(SUBSTITUTE(SUBSTITUTE(SUBSTITUTE(SUBSTITUTE(I18," ",""),"-",""),"(",""),")",""),"+",""),1)="7",LEFT(SUBSTITUTE(SUBSTITUTE(SUBSTITUTE(SUBSTITUTE(SUBSTITUTE(I18," ",""),"-",""),"(",""),")",""),"+",""),1)="8"),ISNUMBER(IFERROR(VALUE(SUBSTITUTE(SUBSTITUTE(SUBSTITUTE(SUBSTITUTE(SUBSTITUTE(I18," ",""),"-",""),"(",""),")",""),"+","")),"x"))),"","Телефон: неверный формат")) | Q18: =TRIM(IF(TRIM(B18)="","Нет наименования. ","")&IF(TRIM(F18)="","Нет адреса. ","")&IF(TRIM(G18)="","Нет контактного лица.","")) | R18: =SUMPRODUCT(--(LEN(K18:Q18)>0)) -> 1 | S18: =IF(R18=0,"Готово к передаче","Требует исправления") -> Требует исправления | T18: =IF(R18=0,"",_xlfn.TEXTJOIN("; ",TRUE(),K18:Q18)) -> ИНН: есть нецифровые символы | U18: =IF(R18=0,"","Здравствуйте! В данных организации «"&B18&"» обнаружены ошибки: "&T18&". Просим проверить и прислать исправленную информацию.") -> Здравствуйте! В данных организации «ООО «Импульс Фуд»» обнаружены ошибки: ИНН: есть нецифровые символы. Просим проверить и прислать исправленную информацию. | V18: =IF(R18>0,COUNTIF($R$2:R18,">0"),"") -> 8 | W18: =IF(R18=0,COUNTIF($R$2:R18,0),"")
A19: 18 | B19: АО «Горизонт Агро» | C19: 6620289584 | D19: 519660661032 | E19: 662043003 | F19: г. Екатеринбург, ул. Центральная, д. 19, оф. 261 | G19: Николаева В. А. | H19: info@gorizont-agro.example | I19: +73435370174 | J19: =IFERROR(VLOOKUP(VALUE(LEFT(C19,2)),Справочники!$A$2:$B$16,2,FALSE()),"не определён") -> Свердловская область | K19: =IF(TRIM(C19)="","ИНН не указан",IF(LEN(C19)<>10,"ИНН: должно быть 10 цифр",IF(NOT(ISNUMBER(IFERROR(VALUE(C19),"x"))),"ИНН: есть нецифровые символы",IF(MOD(MOD(SUMPRODUCT(--MID(C19,{1,2,3,4,5,6,7,8,9},1),{2,4,10,3,5,9,4,6,8}),11),10)=VALUE(RIGHT(C19,1)),"","ИНН: неверная контрольная цифра")))) | L19: =IF(TRIM(D19)="","ОГРН не указан",IF(LEN(D19)<>13,"ОГРН: должно быть 13 цифр",IF(NOT(ISNUMBER(IFERROR(VALUE(D19),"x"))),"ОГРН: есть нецифровые символы",IF(MOD(VALUE(LEFT(D19,12))-11*INT(VALUE(LEFT(D19,12))/11),10)=VALUE(RIGHT(D19,1)),"","ОГРН: неверная контрольная цифра")))) -> ОГРН: должно быть 13 цифр | M19: =IF(TRIM(E19)="","КПП не указан",IF(LEN(E19)<>9,"КПП: должно быть 9 знаков",IF(NOT(AND(ISNUMBER(IFERROR(VALUE(LEFT(E19,4)),"x")),ISNUMBER(IFERROR(VALUE(RIGHT(E19,3)),"x")))),"КПП: неверный формат",IF(LEFT(E19,2)<>LEFT(C19,2),"КПП: код региона не совпадает с ИНН","")))) | N19: =IF(TRIM(C19)="","",IF(COUNTIF($C$2:$C$401,C19)>1,"Дубликат ИНН в реестре","")) | O19: =IF(TRIM(H19)="","Email не указан",IF(AND(ISNUMBER(FIND("@",H19)),ISNUMBER(FIND(".",H19,IFERROR(FIND("@",H19),1))),ISERROR(FIND(" ",H19)),LEFT(H19,1)<>"@",RIGHT(H19,1)<>".",LEN(H19)-LEN(SUBSTITUTE(H19,"@",""))=1),"","Email: неверный формат")) | P19: =IF(TRIM(I19)="","Телефон не указан",IF(AND(LEN(SUBSTITUTE(SUBSTITUTE(SUBSTITUTE(SUBSTITUTE(SUBSTITUTE(I19," ",""),"-",""),"(",""),")",""),"+",""))=11,OR(LEFT(SUBSTITUTE(SUBSTITUTE(SUBSTITUTE(SUBSTITUTE(SUBSTITUTE(I19," ",""),"-",""),"(",""),")",""),"+",""),1)="7",LEFT(SUBSTITUTE(SUBSTITUTE(SUBSTITUTE(SUBSTITUTE(SUBSTITUTE(I19," ",""),"-",""),"(",""),")",""),"+",""),1)="8"),ISNUMBER(IFERROR(VALUE(SUBSTITUTE(SUBSTITUTE(SUBSTITUTE(SUBSTITUTE(SUBSTITUTE(I19," ",""),"-",""),"(",""),")",""),"+","")),"x"))),"","Телефон: неверный формат")) | Q19: =TRIM(IF(TRIM(B19)="","Нет наименования. ","")&IF(TRIM(F19)="","Нет адреса. ","")&IF(TRIM(G19)="","Нет контактного лица.","")) | R19: =SUMPRODUCT(--(LEN(K19:Q19)>0)) -> 1 | S19: =IF(R19=0,"Готово к передаче","Требует исправления") -> Требует исправления | T19: =IF(R19=0,"",_xlfn.TEXTJOIN("; ",TRUE(),K19:Q19)) -> ОГРН: должно быть 13 цифр | U19: =IF(R19=0,"","Здравствуйте! В данных организации «"&B19&"» обнаружены ошибки: "&T19&". Просим проверить и прислать исправленную информацию.") -> Здравствуйте! В данных организации «АО «Горизонт Агро»» обнаружены ошибки: ОГРН: должно быть 13 цифр. Просим проверить и прислать исправленную информацию. | V19: =IF(R19>0,COUNTIF($R$2:R19,">0"),"") -> 9 | W19: =IF(R19=0,COUNTIF($R$2:R19,0),"")
